ERROR 2019-09-12 13:27:36.325 werkzeug _internal - _log: Error on request:
Traceback (most recent call last):
  File "/usr/local/lib/python3.6/dist-packages/werkzeug/serving.py", line 303, in run_wsgi
    execute(self.server.app)
  File "/usr/local/lib/python3.6/dist-packages/werkzeug/serving.py", line 294, in execute
    write(data)
  File "/usr/local/lib/python3.6/dist-packages/werkzeug/serving.py", line 275, in write
    self.wfile.write(data)
  File "/usr/lib/python3.6/socketserver.py", line 803, in write
    self._sock.sendall(b)
OSError: [Errno 113] No route to host
ERROR 2019-09-12 13:27:36.327 werkzeug _internal - _log: Error on request:
Traceback (most recent call last):
  File "/usr/local/lib/python3.6/dist-packages/werkzeug/serving.py", line 303, in run_wsgi
    execute(self.server.app)
  File "/usr/local/lib/python3.6/dist-packages/werkzeug/serving.py", line 294, in execute
    write(data)
  File "/usr/local/lib/python3.6/dist-packages/werkzeug/serving.py", line 275, in write
    self.wfile.write(data)
  File "/usr/lib/python3.6/socketserver.py", line 803, in write
    self._sock.sendall(b)
OSError: [Errno 113] No route to host
ERROR 2019-09-12 13:27:36.328 werkzeug _internal - _log: Error on request:
Traceback (most recent call last):
  File "/usr/local/lib/python3.6/dist-packages/werkzeug/serving.py", line 303, in run_wsgi
    execute(self.server.app)
  File "/usr/local/lib/python3.6/dist-packages/werkzeug/serving.py", line 294, in execute
    write(data)
  File "/usr/local/lib/python3.6/dist-packages/werkzeug/serving.py", line 275, in write
    self.wfile.write(data)
  File "/usr/lib/python3.6/socketserver.py", line 803, in write
    self._sock.sendall(b)
OSError: [Errno 113] No route to host
ERROR 2019-09-12 13:27:38.646 werkzeug _internal - _log: Error on request:
Traceback (most recent call last):
  File "/usr/local/lib/python3.6/dist-packages/werkzeug/serving.py", line 303, in run_wsgi
    execute(self.server.app)
  File "/usr/local/lib/python3.6/dist-packages/werkzeug/serving.py", line 294, in execute
    write(data)
  File "/usr/local/lib/python3.6/dist-packages/werkzeug/serving.py", line 275, in write
    self.wfile.write(data)
  File "/usr/lib/python3.6/socketserver.py", line 803, in write
    self._sock.sendall(b)
OSError: [Errno 113] No route to host
ERROR 2019-09-12 13:27:38.646 werkzeug _internal - _log: Error on request:
Traceback (most recent call last):
  File "/usr/local/lib/python3.6/dist-packages/werkzeug/serving.py", line 303, in run_wsgi
    execute(self.server.app)
  File "/usr/local/lib/python3.6/dist-packages/werkzeug/serving.py", line 294, in execute
    write(data)
  File "/usr/local/lib/python3.6/dist-packages/werkzeug/serving.py", line 275, in write
    self.wfile.write(data)
  File "/usr/lib/python3.6/socketserver.py", line 803, in write
    self._sock.sendall(b)
OSError: [Errno 113] No route to host
