ERROR 2019-09-14 02:26:32.285 werkzeug _internal - _log: Error on request:
Traceback (most recent call last):
  File "/usr/local/lib/python3.6/dist-packages/werkzeug/serving.py", line 303, in run_wsgi
    execute(self.server.app)
  File "/usr/local/lib/python3.6/dist-packages/werkzeug/serving.py", line 294, in execute
    write(data)
  File "/usr/local/lib/python3.6/dist-packages/werkzeug/serving.py", line 275, in write
    self.wfile.write(data)
  File "/usr/lib/python3.6/socketserver.py", line 803, in write
    self._sock.sendall(b)
TimeoutError: [Errno 110] Connection timed out
ERROR 2019-09-14 02:26:32.290 werkzeug _internal - _log: Error on request:
Traceback (most recent call last):
  File "/usr/local/lib/python3.6/dist-packages/werkzeug/serving.py", line 303, in run_wsgi
    execute(self.server.app)
  File "/usr/local/lib/python3.6/dist-packages/werkzeug/serving.py", line 294, in execute
    write(data)
  File "/usr/local/lib/python3.6/dist-packages/werkzeug/serving.py", line 275, in write
    self.wfile.write(data)
  File "/usr/lib/python3.6/socketserver.py", line 803, in write
    self._sock.sendall(b)
TimeoutError: [Errno 110] Connection timed out
ERROR 2019-09-14 02:26:32.292 werkzeug _internal - _log: Error on request:
Traceback (most recent call last):
  File "/usr/local/lib/python3.6/dist-packages/werkzeug/serving.py", line 303, in run_wsgi
    execute(self.server.app)
  File "/usr/local/lib/python3.6/dist-packages/werkzeug/serving.py", line 294, in execute
    write(data)
  File "/usr/local/lib/python3.6/dist-packages/werkzeug/serving.py", line 275, in write
    self.wfile.write(data)
  File "/usr/lib/python3.6/socketserver.py", line 803, in write
    self._sock.sendall(b)
TimeoutError: [Errno 110] Connection timed out
ERROR 2019-09-14 02:27:14.752 werkzeug _internal - _log: Error on request:
Traceback (most recent call last):
  File "/usr/local/lib/python3.6/dist-packages/werkzeug/serving.py", line 303, in run_wsgi
    execute(self.server.app)
  File "/usr/local/lib/python3.6/dist-packages/werkzeug/serving.py", line 294, in execute
    write(data)
  File "/usr/local/lib/python3.6/dist-packages/werkzeug/serving.py", line 275, in write
    self.wfile.write(data)
  File "/usr/lib/python3.6/socketserver.py", line 803, in write
    self._sock.sendall(b)
TimeoutError: [Errno 110] Connection timed out
ERROR 2019-09-14 02:27:16.798 werkzeug _internal - _log: Error on request:
Traceback (most recent call last):
  File "/usr/local/lib/python3.6/dist-packages/werkzeug/serving.py", line 303, in run_wsgi
    execute(self.server.app)
  File "/usr/local/lib/python3.6/dist-packages/werkzeug/serving.py", line 294, in execute
    write(data)
  File "/usr/local/lib/python3.6/dist-packages/werkzeug/serving.py", line 275, in write
    self.wfile.write(data)
  File "/usr/lib/python3.6/socketserver.py", line 803, in write
    self._sock.sendall(b)
TimeoutError: [Errno 110] Connection timed out
ERROR 2019-09-14 02:27:18.847 werkzeug _internal - _log: Error on request:
Traceback (most recent call last):
  File "/usr/local/lib/python3.6/dist-packages/werkzeug/serving.py", line 303, in run_wsgi
    execute(self.server.app)
  File "/usr/local/lib/python3.6/dist-packages/werkzeug/serving.py", line 294, in execute
    write(data)
  File "/usr/local/lib/python3.6/dist-packages/werkzeug/serving.py", line 275, in write
    self.wfile.write(data)
  File "/usr/lib/python3.6/socketserver.py", line 803, in write
    self._sock.sendall(b)
TimeoutError: [Errno 110] Connection timed out
